<?xml version="1.0" encoding="utf-8"?>
<!-- =================================================================================== -->
<!-- |    This document was autogenerated by xacro from legged_robot.urdf.xacro        | -->
<!-- |    EDITING THIS FILE BY HAND IS NOT RECOMMENDED                                 | -->
<!-- =================================================================================== -->
<robot name="legged_robot" xmlns:xacro="http://ros.org/wiki/xacro">
  <material name="Black">
    <color rgba="0.0 0.0 0.0 1.0"/>
  </material>
  <material name="Blue">
    <color rgba="0.0 0.0 0.8 1.0"/>
  </material>
  <material name="Green">
    <color rgba="0.0 0.8 0.0 1.0"/>
  </material>
  <material name="Gray">
    <color rgba="0.7 0.7 0.7 1.0"/>
  </material>
  <material name="DarkGray">
    <color rgba="0.3 0.3 0.3 1.0"/>
  </material>
  <material name="Red">
    <color rgba="0.8 0.0 0.0 1.0"/>
  </material>
  <material name="White">
    <color rgba="1.0 1.0 1.0 1.0"/>
  </material>
  <material name="Yellow">
    <color rgba="0.8 0.8 0.0 1.0"/>
  </material>
  <link name="base_footprint"/>
  <gazebo reference="base_footprint">
    <turnGravityOff>false</turnGravityOff>
  </gazebo>
  <!--body-->
  <link name="base_link">
    <inertial>
      <origin xyz="0 0 0"/>
      <mass value="5.0"/>
      <inertia ixx="0.0385416666667" ixy="0." ixz="0." iyy="0.105208333333" iyz="0." izz="0.105208333333"/>
    </inertial>
    <visual>
      <origin rpy="0 0 0" xyz="0 0 0"/>
      <geometry>
        <box size="0.5 0.3 0.05"/>
      </geometry>
      <material name="Gray"/>
    </visual>
    <collision>
      <origin rpy="0 0 0" xyz="0 0 0"/>
      <geometry>
        <box size="0.5 0.3 0.05"/>
      </geometry>
    </collision>
  </link>
  <joint name="base_link_joint" type="fixed">
    <origin rpy="0 0 0" xyz="0 0 0"/>
    <parent link="base_footprint"/>
    <child link="base_link"/>
  </joint>
  <!--fr : front, rear ; lr: left, right -->
  <link name="base_left_front">
    <visual>
      <geometry>
        <cylinder length="0.05" radius="0.025"/>
      </geometry>
      <material name="Black"/>
    </visual>
    <collision>
      <origin rpy="0 0 0 " xyz="0 0 0"/>
      <geometry>
        <cylinder length="0.05" radius="0.025"/>
      </geometry>
    </collision>
    <inertial>
      <origin xyz="0 0 0"/>
      <mass value="0.5"/>
      <inertia ixx="0.000182291666667" ixy="0" ixz="0" iyy="0.000182291666667" iyz="0" izz="0.00015625"/>
    </inertial>
  </link>
  <link name="serbo_left_front">
    <visual>
      <geometry>
        <cylinder length="0.05" radius="0.025"/>
      </geometry>
      <material name="Black"/>
    </visual>
    <collision>
      <origin rpy="0 0 0 " xyz="0 0 0"/>
      <geometry>
        <cylinder length="0.05" radius="0.025"/>
      </geometry>
    </collision>
    <inertial>
      <origin xyz="0 0 0"/>
      <mass value="0.5"/>
      <inertia ixx="0.000182291666667" ixy="0" ixz="0" iyy="0.000182291666667" iyz="0" izz="0.00015625"/>
    </inertial>
  </link>
  <joint name="serbo_left_front_joint" type="fixed">
    <parent link="link_left_front_upper"/>
    <child link="serbo_left_front"/>
    <origin rpy="1.5707 0 0" xyz="0 0 0.2"/>
  </joint>
  <link name="link_left_front_lower">
    <inertial>
      <origin xyz="0 0 0.15"/>
      <mass value="2.0"/>
      <inertia ixx="0.01505" ixy="0" ixz="0" iyy="0.01505" iyz="0" izz="0.0001"/>
    </inertial>
    <collision>
      <origin rpy="0 0 0" xyz="0 0 0.15"/>
      <geometry>
        <cylinder length="0.3" radius="0.01"/>
      </geometry>
    </collision>
    <visual>
      <origin rpy="0 0 0" xyz="0 0 0.15"/>
      <geometry>
        <cylinder length="0.3" radius="0.01"/>
      </geometry>
      <material name="Gray"/>
    </visual>
  </link>
  <link name="link_left_front_upper">
    <inertial>
      <origin xyz="0 0 0.1"/>
      <mass value="2.0"/>
      <inertia ixx="0.00686666666667" ixy="0" ixz="0" iyy="0.00686666666667" iyz="0" izz="0.0004"/>
    </inertial>
    <collision>
      <origin rpy="0 0 0" xyz="0 0 0.1"/>
      <geometry>
        <cylinder length="0.2" radius="0.02"/>
      </geometry>
    </collision>
    <visual>
      <origin rpy="0 0 0" xyz="0 0 0.1"/>
      <geometry>
        <cylinder length="0.2" radius="0.02"/>
      </geometry>
      <material name="Gray"/>
    </visual>
  </link>
  <link name="ball_left_front">
    <visual>
      <geometry>
        <sphere radius="0.02"/>
      </geometry>
      <material name="Black"/>
    </visual>
    <collision>
      <origin rpy="0 0 0 " xyz="0 0 0"/>
      <geometry>
        <sphere radius="0.02"/>
      </geometry>
    </collision>
    <inertial>
      <origin xyz="0 0 0"/>
      <mass value="0.02"/>
      <inertia ixx="3.2e-06" ixy="0" ixz="0" iyy="3.2e-06}" iyz="0" izz="3.2e-06"/>
    </inertial>
  </link>
  <joint name="ball_left_front_joint" type="fixed">
    <parent link="link_left_front_lower"/>
    <child link="ball_left_front"/>
    <origin rpy="0 0 0" xyz="0 0 0.3"/>
  </joint>
  <!--joint-->
  <!--1st joint-->
  <joint name="hinge_left_front_1" type="revolute">
    <parent link="base_link"/>
    <child link="base_left_front"/>
    <origin rpy="1.5707 0.785 0" xyz="0.23 0.17 0.0"/>
    <axis xyz="0 0 1"/>
    <limit effort="1000" lower="-0.3926875" upper="0.785" velocity="100.0"/>
  </joint>
  <!--2nd joint-->
  <joint name="hinge_left_front_2" type="revolute">
    <parent link="base_left_front"/>
    <child link="link_left_front_upper"/>
    <origin rpy="1.5707 0 0" xyz="0 0 0"/>
    <axis xyz="1 0 0"/>
    <limit effort="1000" lower="-0.1963" upper="0.1963" velocity="100.0"/>
  </joint>
  <!--3rd joint-->
  <joint name="hinge_left_front_3" type="revolute">
    <parent link="serbo_left_front"/>
    <child link="link_left_front_lower"/>
    <origin rpy="0 1.5707 0" xyz="0 0 0"/>
    <axis xyz="1 0 0"/>
    <limit effort="1000" lower="-0.785" upper="0.785" velocity="100.0"/>
  </joint>
  <!-- =========gazebo reference============ -->
  <gazebo reference="base_left_front">
    <selfCollide value="false"/>
    <material>Gazebo/Black</material>
    <turnGravityOff>false</turnGravityOff>
  </gazebo>
  <gazebo reference="link_left_front_lower">
    <selfCollide value="false"/>
    <mu1 value="10000.0"/>
    <mu2 value="10000.0"/>
    <kp value="10000000.0"/>
    <kd value="1.0"/>
    <fdir1 value="1 0 0"/>
    <material>Gazebo/Gray</material>
    <turnGravityOff>false</turnGravityOff>
  </gazebo>
  <gazebo reference="link_left_front_upper">
    <selfCollide value="false"/>
    <mu1 value="10000.0"/>
    <mu2 value="10000.0"/>
    <kp value="10000000.0"/>
    <kd value="1.0"/>
    <fdir1 value="1 0 0"/>
    <material>Gazebo/Gray</material>
    <turnGravityOff>false</turnGravityOff>
  </gazebo>
  <gazebo reference="ball_left_front">
    <selfCollide value="false"/>
    <mu1 value="10000.0"/>
    <mu2 value="10000.0"/>
    <kp value="10000000.0"/>
    <kd value="1.0"/>
    <fdir1 value="1 0 0"/>
    <material>Gazebo/Black</material>
    <turnGravityOff>false</turnGravityOff>
  </gazebo>
  <gazebo reference="serbo_left_front">
    <selfCollide value="false"/>
    <mu1 value="10000.0"/>
    <mu2 value="10000.0"/>
    <kp value="10000000.0"/>
    <kd value="1.0"/>
    <fdir1 value="1 0 0"/>
    <material>Gazebo/Black</material>
    <turnGravityOff>false</turnGravityOff>
  </gazebo>
  <!-- Transmission is important to link the joints and the controller -->
  <transmission name="hinge_left_front_1_trans">
    <type>transmission_interface/SimpleTransmission</type>
    <joint name="hinge_left_front_1">
      <hardwareInterface>hardware_interface/EffortJointInterface</hardwareInterface>
    </joint>
    <actuator name="hinge_left_front_1_motor">
      <mechanicalReduction>1</mechanicalReduction>
    </actuator>
  </transmission>
  <transmission name="hinge_left_front_2_trans">
    <type>transmission_interface/SimpleTransmission</type>
    <joint name="hinge_left_front_2">
      <hardwareInterface>hardware_interface/EffortJointInterface</hardwareInterface>
    </joint>
    <actuator name="hinge_left_front_2_motor">
      <mechanicalReduction>1</mechanicalReduction>
    </actuator>
  </transmission>
  <transmission name="hinge_left_front_3_trans">
    <type>transmission_interface/SimpleTransmission</type>
    <joint name="hinge_left_front_3">
      <hardwareInterface>hardware_interface/EffortJointInterface</hardwareInterface>
    </joint>
    <actuator name="hinge_left_front_3_motor">
      <mechanicalReduction>1</mechanicalReduction>
    </actuator>
  </transmission>
  <!--fr : front, rear ; lr: left, right -->
  <link name="base_right_front">
    <visual>
      <geometry>
        <cylinder length="0.05" radius="0.025"/>
      </geometry>
      <material name="Black"/>
    </visual>
    <collision>
      <origin rpy="0 0 0 " xyz="0 0 0"/>
      <geometry>
        <cylinder length="0.05" radius="0.025"/>
      </geometry>
    </collision>
    <inertial>
      <origin xyz="0 0 0"/>
      <mass value="0.5"/>
      <inertia ixx="0.000182291666667" ixy="0" ixz="0" iyy="0.000182291666667" iyz="0" izz="0.00015625"/>
    </inertial>
  </link>
  <link name="serbo_right_front">
    <visual>
      <geometry>
        <cylinder length="0.05" radius="0.025"/>
      </geometry>
      <material name="Black"/>
    </visual>
    <collision>
      <origin rpy="0 0 0 " xyz="0 0 0"/>
      <geometry>
        <cylinder length="0.05" radius="0.025"/>
      </geometry>
    </collision>
    <inertial>
      <origin xyz="0 0 0"/>
      <mass value="0.5"/>
      <inertia ixx="0.000182291666667" ixy="0" ixz="0" iyy="0.000182291666667" iyz="0" izz="0.00015625"/>
    </inertial>
  </link>
  <joint name="serbo_right_front_joint" type="fixed">
    <parent link="link_right_front_upper"/>
    <child link="serbo_right_front"/>
    <origin rpy="1.5707 0 0" xyz="0 0 0.2"/>
  </joint>
  <link name="link_right_front_lower">
    <inertial>
      <origin xyz="0 0 0.15"/>
      <mass value="2.0"/>
      <inertia ixx="0.01505" ixy="0" ixz="0" iyy="0.01505" iyz="0" izz="0.0001"/>
    </inertial>
    <collision>
      <origin rpy="0 0 0" xyz="0 0 0.15"/>
      <geometry>
        <cylinder length="0.3" radius="0.01"/>
      </geometry>
    </collision>
    <visual>
      <origin rpy="0 0 0" xyz="0 0 0.15"/>
      <geometry>
        <cylinder length="0.3" radius="0.01"/>
      </geometry>
      <material name="Gray"/>
    </visual>
  </link>
  <link name="link_right_front_upper">
    <inertial>
      <origin xyz="0 0 0.1"/>
      <mass value="2.0"/>
      <inertia ixx="0.00686666666667" ixy="0" ixz="0" iyy="0.00686666666667" iyz="0" izz="0.0004"/>
    </inertial>
    <collision>
      <origin rpy="0 0 0" xyz="0 0 0.1"/>
      <geometry>
        <cylinder length="0.2" radius="0.02"/>
      </geometry>
    </collision>
    <visual>
      <origin rpy="0 0 0" xyz="0 0 0.1"/>
      <geometry>
        <cylinder length="0.2" radius="0.02"/>
      </geometry>
      <material name="Gray"/>
    </visual>
  </link>
  <link name="ball_right_front">
    <visual>
      <geometry>
        <sphere radius="0.02"/>
      </geometry>
      <material name="Black"/>
    </visual>
    <collision>
      <origin rpy="0 0 0 " xyz="0 0 0"/>
      <geometry>
        <sphere radius="0.02"/>
      </geometry>
    </collision>
    <inertial>
      <origin xyz="0 0 0"/>
      <mass value="0.02"/>
      <inertia ixx="3.2e-06" ixy="0" ixz="0" iyy="3.2e-06}" iyz="0" izz="3.2e-06"/>
    </inertial>
  </link>
  <joint name="ball_right_front_joint" type="fixed">
    <parent link="link_right_front_lower"/>
    <child link="ball_right_front"/>
    <origin rpy="0 0 0" xyz="0 0 0.3"/>
  </joint>
  <!--joint-->
  <!--1st joint-->
  <joint name="hinge_right_front_1" type="revolute">
    <parent link="base_link"/>
    <child link="base_right_front"/>
    <origin rpy="1.5707 0.785 0" xyz="0.23 -0.17 0.0"/>
    <axis xyz="0 0 1"/>
    <limit effort="1000" lower="-0.3926875" upper="0.785" velocity="100.0"/>
  </joint>
  <!--2nd joint-->
  <joint name="hinge_right_front_2" type="revolute">
    <parent link="base_right_front"/>
    <child link="link_right_front_upper"/>
    <origin rpy="1.5707 0 0" xyz="0 0 0"/>
    <axis xyz="1 0 0"/>
    <limit effort="1000" lower="-0.1963" upper="0.1963" velocity="100.0"/>
  </joint>
  <!--3rd joint-->
  <joint name="hinge_right_front_3" type="revolute">
    <parent link="serbo_right_front"/>
    <child link="link_right_front_lower"/>
    <origin rpy="0 1.5707 0" xyz="0 0 0"/>
    <axis xyz="1 0 0"/>
    <limit effort="1000" lower="-0.785" upper="0.785" velocity="100.0"/>
  </joint>
  <!-- =========gazebo reference============ -->
  <gazebo reference="base_right_front">
    <selfCollide value="false"/>
    <material>Gazebo/Black</material>
    <turnGravityOff>false</turnGravityOff>
  </gazebo>
  <gazebo reference="link_right_front_lower">
    <selfCollide value="false"/>
    <mu1 value="10000.0"/>
    <mu2 value="10000.0"/>
    <kp value="10000000.0"/>
    <kd value="1.0"/>
    <fdir1 value="1 0 0"/>
    <material>Gazebo/Gray</material>
    <turnGravityOff>false</turnGravityOff>
  </gazebo>
  <gazebo reference="link_right_front_upper">
    <selfCollide value="false"/>
    <mu1 value="10000.0"/>
    <mu2 value="10000.0"/>
    <kp value="10000000.0"/>
    <kd value="1.0"/>
    <fdir1 value="1 0 0"/>
    <material>Gazebo/Gray</material>
    <turnGravityOff>false</turnGravityOff>
  </gazebo>
  <gazebo reference="ball_right_front">
    <selfCollide value="false"/>
    <mu1 value="10000.0"/>
    <mu2 value="10000.0"/>
    <kp value="10000000.0"/>
    <kd value="1.0"/>
    <fdir1 value="1 0 0"/>
    <material>Gazebo/Black</material>
    <turnGravityOff>false</turnGravityOff>
  </gazebo>
  <gazebo reference="serbo_right_front">
    <selfCollide value="false"/>
    <mu1 value="10000.0"/>
    <mu2 value="10000.0"/>
    <kp value="10000000.0"/>
    <kd value="1.0"/>
    <fdir1 value="1 0 0"/>
    <material>Gazebo/Black</material>
    <turnGravityOff>false</turnGravityOff>
  </gazebo>
  <!-- Transmission is important to link the joints and the controller -->
  <transmission name="hinge_right_front_1_trans">
    <type>transmission_interface/SimpleTransmission</type>
    <joint name="hinge_right_front_1">
      <hardwareInterface>hardware_interface/EffortJointInterface</hardwareInterface>
    </joint>
    <actuator name="hinge_right_front_1_motor">
      <mechanicalReduction>1</mechanicalReduction>
    </actuator>
  </transmission>
  <transmission name="hinge_right_front_2_trans">
    <type>transmission_interface/SimpleTransmission</type>
    <joint name="hinge_right_front_2">
      <hardwareInterface>hardware_interface/EffortJointInterface</hardwareInterface>
    </joint>
    <actuator name="hinge_right_front_2_motor">
      <mechanicalReduction>1</mechanicalReduction>
    </actuator>
  </transmission>
  <transmission name="hinge_right_front_3_trans">
    <type>transmission_interface/SimpleTransmission</type>
    <joint name="hinge_right_front_3">
      <hardwareInterface>hardware_interface/EffortJointInterface</hardwareInterface>
    </joint>
    <actuator name="hinge_right_front_3_motor">
      <mechanicalReduction>1</mechanicalReduction>
    </actuator>
  </transmission>
  <!--fr : front, rear ; lr: left, right -->
  <link name="base_left_rear">
    <visual>
      <geometry>
        <cylinder length="0.05" radius="0.025"/>
      </geometry>
      <material name="Black"/>
    </visual>
    <collision>
      <origin rpy="0 0 0 " xyz="0 0 0"/>
      <geometry>
        <cylinder length="0.05" radius="0.025"/>
      </geometry>
    </collision>
    <inertial>
      <origin xyz="0 0 0"/>
      <mass value="0.5"/>
      <inertia ixx="0.000182291666667" ixy="0" ixz="0" iyy="0.000182291666667" iyz="0" izz="0.00015625"/>
    </inertial>
  </link>
  <link name="serbo_left_rear">
    <visual>
      <geometry>
        <cylinder length="0.05" radius="0.025"/>
      </geometry>
      <material name="Black"/>
    </visual>
    <collision>
      <origin rpy="0 0 0 " xyz="0 0 0"/>
      <geometry>
        <cylinder length="0.05" radius="0.025"/>
      </geometry>
    </collision>
    <inertial>
      <origin xyz="0 0 0"/>
      <mass value="0.5"/>
      <inertia ixx="0.000182291666667" ixy="0" ixz="0" iyy="0.000182291666667" iyz="0" izz="0.00015625"/>
    </inertial>
  </link>
  <joint name="serbo_left_rear_joint" type="fixed">
    <parent link="link_left_rear_upper"/>
    <child link="serbo_left_rear"/>
    <origin rpy="1.5707 0 0" xyz="0 0 0.2"/>
  </joint>
  <link name="link_left_rear_lower">
    <inertial>
      <origin xyz="0 0 0.15"/>
      <mass value="2.0"/>
      <inertia ixx="0.01505" ixy="0" ixz="0" iyy="0.01505" iyz="0" izz="0.0001"/>
    </inertial>
    <collision>
      <origin rpy="0 0 0" xyz="0 0 0.15"/>
      <geometry>
        <cylinder length="0.3" radius="0.01"/>
      </geometry>
    </collision>
    <visual>
      <origin rpy="0 0 0" xyz="0 0 0.15"/>
      <geometry>
        <cylinder length="0.3" radius="0.01"/>
      </geometry>
      <material name="Gray"/>
    </visual>
  </link>
  <link name="link_left_rear_upper">
    <inertial>
      <origin xyz="0 0 0.1"/>
      <mass value="2.0"/>
      <inertia ixx="0.00686666666667" ixy="0" ixz="0" iyy="0.00686666666667" iyz="0" izz="0.0004"/>
    </inertial>
    <collision>
      <origin rpy="0 0 0" xyz="0 0 0.1"/>
      <geometry>
        <cylinder length="0.2" radius="0.02"/>
      </geometry>
    </collision>
    <visual>
      <origin rpy="0 0 0" xyz="0 0 0.1"/>
      <geometry>
        <cylinder length="0.2" radius="0.02"/>
      </geometry>
      <material name="Gray"/>
    </visual>
  </link>
  <link name="ball_left_rear">
    <visual>
      <geometry>
        <sphere radius="0.02"/>
      </geometry>
      <material name="Black"/>
    </visual>
    <collision>
      <origin rpy="0 0 0 " xyz="0 0 0"/>
      <geometry>
        <sphere radius="0.02"/>
      </geometry>
    </collision>
    <inertial>
      <origin xyz="0 0 0"/>
      <mass value="0.02"/>
      <inertia ixx="3.2e-06" ixy="0" ixz="0" iyy="3.2e-06}" iyz="0" izz="3.2e-06"/>
    </inertial>
  </link>
  <joint name="ball_left_rear_joint" type="fixed">
    <parent link="link_left_rear_lower"/>
    <child link="ball_left_rear"/>
    <origin rpy="0 0 0" xyz="0 0 0.3"/>
  </joint>
  <!--joint-->
  <!--1st joint-->
  <joint name="hinge_left_rear_1" type="revolute">
    <parent link="base_link"/>
    <child link="base_left_rear"/>
    <origin rpy="1.5707 0.785 0" xyz="-0.23 0.17 0.0"/>
    <axis xyz="0 0 1"/>
    <limit effort="1000" lower="-0.3926875" upper="0.785" velocity="100.0"/>
  </joint>
  <!--2nd joint-->
  <joint name="hinge_left_rear_2" type="revolute">
    <parent link="base_left_rear"/>
    <child link="link_left_rear_upper"/>
    <origin rpy="1.5707 0 0" xyz="0 0 0"/>
    <axis xyz="1 0 0"/>
    <limit effort="1000" lower="-0.1963" upper="0.1963" velocity="100.0"/>
  </joint>
  <!--3rd joint-->
  <joint name="hinge_left_rear_3" type="revolute">
    <parent link="serbo_left_rear"/>
    <child link="link_left_rear_lower"/>
    <origin rpy="0 1.5707 0" xyz="0 0 0"/>
    <axis xyz="1 0 0"/>
    <limit effort="1000" lower="-0.785" upper="0.785" velocity="100.0"/>
  </joint>
  <!-- =========gazebo reference============ -->
  <gazebo reference="base_left_rear">
    <selfCollide value="false"/>
    <material>Gazebo/Black</material>
    <turnGravityOff>false</turnGravityOff>
  </gazebo>
  <gazebo reference="link_left_rear_lower">
    <selfCollide value="false"/>
    <mu1 value="10000.0"/>
    <mu2 value="10000.0"/>
    <kp value="10000000.0"/>
    <kd value="1.0"/>
    <fdir1 value="1 0 0"/>
    <material>Gazebo/Gray</material>
    <turnGravityOff>false</turnGravityOff>
  </gazebo>
  <gazebo reference="link_left_rear_upper">
    <selfCollide value="false"/>
    <mu1 value="10000.0"/>
    <mu2 value="10000.0"/>
    <kp value="10000000.0"/>
    <kd value="1.0"/>
    <fdir1 value="1 0 0"/>
    <material>Gazebo/Gray</material>
    <turnGravityOff>false</turnGravityOff>
  </gazebo>
  <gazebo reference="ball_left_rear">
    <selfCollide value="false"/>
    <mu1 value="10000.0"/>
    <mu2 value="10000.0"/>
    <kp value="10000000.0"/>
    <kd value="1.0"/>
    <fdir1 value="1 0 0"/>
    <material>Gazebo/Black</material>
    <turnGravityOff>false</turnGravityOff>
  </gazebo>
  <gazebo reference="serbo_left_rear">
    <selfCollide value="false"/>
    <mu1 value="10000.0"/>
    <mu2 value="10000.0"/>
    <kp value="10000000.0"/>
    <kd value="1.0"/>
    <fdir1 value="1 0 0"/>
    <material>Gazebo/Black</material>
    <turnGravityOff>false</turnGravityOff>
  </gazebo>
  <!-- Transmission is important to link the joints and the controller -->
  <transmission name="hinge_left_rear_1_trans">
    <type>transmission_interface/SimpleTransmission</type>
    <joint name="hinge_left_rear_1">
      <hardwareInterface>hardware_interface/EffortJointInterface</hardwareInterface>
    </joint>
    <actuator name="hinge_left_rear_1_motor">
      <mechanicalReduction>1</mechanicalReduction>
    </actuator>
  </transmission>
  <transmission name="hinge_left_rear_2_trans">
    <type>transmission_interface/SimpleTransmission</type>
    <joint name="hinge_left_rear_2">
      <hardwareInterface>hardware_interface/EffortJointInterface</hardwareInterface>
    </joint>
    <actuator name="hinge_left_rear_2_motor">
      <mechanicalReduction>1</mechanicalReduction>
    </actuator>
  </transmission>
  <transmission name="hinge_left_rear_3_trans">
    <type>transmission_interface/SimpleTransmission</type>
    <joint name="hinge_left_rear_3">
      <hardwareInterface>hardware_interface/EffortJointInterface</hardwareInterface>
    </joint>
    <actuator name="hinge_left_rear_3_motor">
      <mechanicalReduction>1</mechanicalReduction>
    </actuator>
  </transmission>
  <!--fr : front, rear ; lr: left, right -->
  <link name="base_right_rear">
    <visual>
      <geometry>
        <cylinder length="0.05" radius="0.025"/>
      </geometry>
      <material name="Black"/>
    </visual>
    <collision>
      <origin rpy="0 0 0 " xyz="0 0 0"/>
      <geometry>
        <cylinder length="0.05" radius="0.025"/>
      </geometry>
    </collision>
    <inertial>
      <origin xyz="0 0 0"/>
      <mass value="0.5"/>
      <inertia ixx="0.000182291666667" ixy="0" ixz="0" iyy="0.000182291666667" iyz="0" izz="0.00015625"/>
    </inertial>
  </link>
  <link name="serbo_right_rear">
    <visual>
      <geometry>
        <cylinder length="0.05" radius="0.025"/>
      </geometry>
      <material name="Black"/>
    </visual>
    <collision>
      <origin rpy="0 0 0 " xyz="0 0 0"/>
      <geometry>
        <cylinder length="0.05" radius="0.025"/>
      </geometry>
    </collision>
    <inertial>
      <origin xyz="0 0 0"/>
      <mass value="0.5"/>
      <inertia ixx="0.000182291666667" ixy="0" ixz="0" iyy="0.000182291666667" iyz="0" izz="0.00015625"/>
    </inertial>
  </link>
  <joint name="serbo_right_rear_joint" type="fixed">
    <parent link="link_right_rear_upper"/>
    <child link="serbo_right_rear"/>
    <origin rpy="1.5707 0 0" xyz="0 0 0.2"/>
  </joint>
  <link name="link_right_rear_lower">
    <inertial>
      <origin xyz="0 0 0.15"/>
      <mass value="2.0"/>
      <inertia ixx="0.01505" ixy="0" ixz="0" iyy="0.01505" iyz="0" izz="0.0001"/>
    </inertial>
    <collision>
      <origin rpy="0 0 0" xyz="0 0 0.15"/>
      <geometry>
        <cylinder length="0.3" radius="0.01"/>
      </geometry>
    </collision>
    <visual>
      <origin rpy="0 0 0" xyz="0 0 0.15"/>
      <geometry>
        <cylinder length="0.3" radius="0.01"/>
      </geometry>
      <material name="Gray"/>
    </visual>
  </link>
  <link name="link_right_rear_upper">
    <inertial>
      <origin xyz="0 0 0.1"/>
      <mass value="2.0"/>
      <inertia ixx="0.00686666666667" ixy="0" ixz="0" iyy="0.00686666666667" iyz="0" izz="0.0004"/>
    </inertial>
    <collision>
      <origin rpy="0 0 0" xyz="0 0 0.1"/>
      <geometry>
        <cylinder length="0.2" radius="0.02"/>
      </geometry>
    </collision>
    <visual>
      <origin rpy="0 0 0" xyz="0 0 0.1"/>
      <geometry>
        <cylinder length="0.2" radius="0.02"/>
      </geometry>
      <material name="Gray"/>
    </visual>
  </link>
  <link name="ball_right_rear">
    <visual>
      <geometry>
        <sphere radius="0.02"/>
      </geometry>
      <material name="Black"/>
    </visual>
    <collision>
      <origin rpy="0 0 0 " xyz="0 0 0"/>
      <geometry>
        <sphere radius="0.02"/>
      </geometry>
    </collision>
    <inertial>
      <origin xyz="0 0 0"/>
      <mass value="0.02"/>
      <inertia ixx="3.2e-06" ixy="0" ixz="0" iyy="3.2e-06}" iyz="0" izz="3.2e-06"/>
    </inertial>
  </link>
  <joint name="ball_right_rear_joint" type="fixed">
    <parent link="link_right_rear_lower"/>
    <child link="ball_right_rear"/>
    <origin rpy="0 0 0" xyz="0 0 0.3"/>
  </joint>
  <!--joint-->
  <!--1st joint-->
  <joint name="hinge_right_rear_1" type="revolute">
    <parent link="base_link"/>
    <child link="base_right_rear"/>
    <origin rpy="1.5707 0.785 0" xyz="-0.23 -0.17 0.0"/>
    <axis xyz="0 0 1"/>
    <limit effort="1000" lower="-0.3926875" upper="0.785" velocity="100.0"/>
  </joint>
  <!--2nd joint-->
  <joint name="hinge_right_rear_2" type="revolute">
    <parent link="base_right_rear"/>
    <child link="link_right_rear_upper"/>
    <origin rpy="1.5707 0 0" xyz="0 0 0"/>
    <axis xyz="1 0 0"/>
    <limit effort="1000" lower="-0.1963" upper="0.1963" velocity="100.0"/>
  </joint>
  <!--3rd joint-->
  <joint name="hinge_right_rear_3" type="revolute">
    <parent link="serbo_right_rear"/>
    <child link="link_right_rear_lower"/>
    <origin rpy="0 1.5707 0" xyz="0 0 0"/>
    <axis xyz="1 0 0"/>
    <limit effort="1000" lower="-0.785" upper="0.785" velocity="100.0"/>
  </joint>
  <!-- =========gazebo reference============ -->
  <gazebo reference="base_right_rear">
    <selfCollide value="false"/>
    <material>Gazebo/Black</material>
    <turnGravityOff>false</turnGravityOff>
  </gazebo>
  <gazebo reference="link_right_rear_lower">
    <selfCollide value="false"/>
    <mu1 value="10000.0"/>
    <mu2 value="10000.0"/>
    <kp value="10000000.0"/>
    <kd value="1.0"/>
    <fdir1 value="1 0 0"/>
    <material>Gazebo/Gray</material>
    <turnGravityOff>false</turnGravityOff>
  </gazebo>
  <gazebo reference="link_right_rear_upper">
    <selfCollide value="false"/>
    <mu1 value="10000.0"/>
    <mu2 value="10000.0"/>
    <kp value="10000000.0"/>
    <kd value="1.0"/>
    <fdir1 value="1 0 0"/>
    <material>Gazebo/Gray</material>
    <turnGravityOff>false</turnGravityOff>
  </gazebo>
  <gazebo reference="ball_right_rear">
    <selfCollide value="false"/>
    <mu1 value="10000.0"/>
    <mu2 value="10000.0"/>
    <kp value="10000000.0"/>
    <kd value="1.0"/>
    <fdir1 value="1 0 0"/>
    <material>Gazebo/Black</material>
    <turnGravityOff>false</turnGravityOff>
  </gazebo>
  <gazebo reference="serbo_right_rear">
    <selfCollide value="false"/>
    <mu1 value="10000.0"/>
    <mu2 value="10000.0"/>
    <kp value="10000000.0"/>
    <kd value="1.0"/>
    <fdir1 value="1 0 0"/>
    <material>Gazebo/Black</material>
    <turnGravityOff>false</turnGravityOff>
  </gazebo>
  <!-- Transmission is important to link the joints and the controller -->
  <transmission name="hinge_right_rear_1_trans">
    <type>transmission_interface/SimpleTransmission</type>
    <joint name="hinge_right_rear_1">
      <hardwareInterface>hardware_interface/EffortJointInterface</hardwareInterface>
    </joint>
    <actuator name="hinge_right_rear_1_motor">
      <mechanicalReduction>1</mechanicalReduction>
    </actuator>
  </transmission>
  <transmission name="hinge_right_rear_2_trans">
    <type>transmission_interface/SimpleTransmission</type>
    <joint name="hinge_right_rear_2">
      <hardwareInterface>hardware_interface/EffortJointInterface</hardwareInterface>
    </joint>
    <actuator name="hinge_right_rear_2_motor">
      <mechanicalReduction>1</mechanicalReduction>
    </actuator>
  </transmission>
  <transmission name="hinge_right_rear_3_trans">
    <type>transmission_interface/SimpleTransmission</type>
    <joint name="hinge_right_rear_3">
      <hardwareInterface>hardware_interface/EffortJointInterface</hardwareInterface>
    </joint>
    <actuator name="hinge_right_rear_3_motor">
      <mechanicalReduction>1</mechanicalReduction>
    </actuator>
  </transmission>
  <!-- =========gazebo reference============ -->
  <gazebo reference="base_link">
    <material>Gazebo/Gray</material>
    <turnGravityOff>false</turnGravityOff>
  </gazebo>
  <gazebo>
    <plugin filename="libgazebo_ros_legged_robot.so" name="gazebo_ros_legged_robot">
      <commandTopic>/legged_robot/cmd_ang</commandTopic>
      <hinge_lf1>hinge_left_front_1</hinge_lf1>
      <hinge_lf2>hinge_left_front_2</hinge_lf2>
      <hinge_lf3>hinge_left_front_3</hinge_lf3>
      <hinge_lr1>hinge_left_rear_1</hinge_lr1>
      <hinge_lr2>hinge_left_rear_2</hinge_lr2>
      <hinge_lr3>hinge_left_rear_3</hinge_lr3>
      <hinge_rf1>hinge_right_front_1</hinge_rf1>
      <hinge_rf2>hinge_right_front_2</hinge_rf2>
      <hinge_rf3>hinge_right_front_3</hinge_rf3>
      <hinge_rr1>hinge_right_rear_1</hinge_rr1>
      <hinge_rr2>hinge_right_rear_2</hinge_rr2>
      <hinge_rr3>hinge_right_rear_3</hinge_rr3>
      <gain>0.1</gain>
      <hingeTorque>100.0</hingeTorque>
      <publishHingeTF>false</publishHingeTF>
    </plugin>
  </gazebo>
</robot>

